File: practicaRayosX/MnO2.csv
[Measurement conditions]
Sample identification,MnO2
Comment - 1,"Configuration=Plataforma Reflexion-Transmision spinner, Owner=User-1, Creation date=2/3/2023 7:20:03 AM"
Comment - 2,"Goniometer=Omega/2Theta; Minimum step size 2Theta:0.0001; Minimum step size Omega:0.0001"
Comment - 3,"Sample stage=Reflection-transmission spinner; Minimum step size Phi:0.1"
Comment - 4,"Diffractometer system=EMPYREAN"
Comment - 5,"Measurement program=C:\PANalytical\Data Collector\Programs\DRX01-005-5-80.xrdmp, Identifier={D2D94ECF-D8E1-4D65-A9F1-1EA3648327E6}"
Comment - 6,"Batch program=C:\PANalytical\Data Collector\Programs\BATCH.xrdmp, Identifier={1A5E0411-49C0-46C9-A459-383431844E05}"
Anode material,Cu
K-Alpha1 wavelength,1.5405980
K-Alpha2 wavelength,1.5444260
Ratio K-Alpha2/K-Alpha1,0.500
Divergence slit,Fixed,0.5
Monochromator used,NO
Generator voltage, 45
Tube current, 40
File date and time,07/Mar/2023 13:57
Unit cell,
h k l, 0 0 0
Scan axis,Gonio
Scan range,4.999799996,79.999969724
Scan step size,0.0525211
No. of points, 1428
Scan type,CONTINUOUS
Phi,67.4
Time per step,44.880
[Scan points]
Angle,Intensity
5.026060560,4996.0
5.078581687,5023.0
5.131102815,4943.0
5.183623942,4962.0
5.236145069,4898.0
5.288666196,4842.0
5.341187324,4799.0
5.393708451,4681.0
5.446229578,4759.0
5.498750705,4620.0
5.551271833,4608.0
5.603792960,4642.0
5.656314087,4530.0
5.708835214,4603.0
5.761356342,4498.0
5.813877469,4326.0
5.866398596,4509.0
5.918919723,4509.0
5.971440851,4321.0
6.023961978,4310.0
6.076483105,4413.0
6.129004232,4381.0
6.181525360,4372.0
6.234046487,4339.0
6.286567614,4288.0
6.339088741,4416.0
6.391609869,4274.0
6.444130996,4415.0
6.496652123,4359.0
6.549173251,4463.0
6.601694378,4366.0
6.654215505,4372.0
6.706736632,4280.0
6.759257760,4457.0
6.811778887,4277.0
6.864300014,4293.0
6.916821141,4400.0
6.969342269,4290.0
7.021863396,4318.0
7.074384523,4283.0
7.126905650,4325.0
7.179426778,4258.0
7.231947905,4275.0
7.284469032,4402.0
7.336990159,4382.0
7.389511287,4249.0
7.442032414,4316.0
7.494553541,4330.0
7.547074668,4260.0
7.599595796,4303.0
7.652116923,4256.0
7.704638050,4306.0
7.757159178,4308.0
7.809680305,4193.0
7.862201432,4195.0
7.914722559,4296.0
7.967243687,4207.0
8.019764814,4262.0
8.072285941,4241.0
8.124807068,4199.0
8.177328196,4204.0
8.229849323,4253.0
8.282370450,4208.0
8.334891577,4271.0
8.387412705,4156.0
8.439933832,4232.0
8.492454959,4256.0
8.544976086,4098.0
8.597497214,4170.0
8.650018341,4183.0
8.702539468,4138.0
8.755060595,4203.0
8.807581723,4093.0
8.860102850,4056.0
8.912623977,4091.0
8.965145104,4220.0
9.017666232,4021.0
9.070187359,4033.0
9.122708486,4073.0
9.175229614,4028.0
9.227750741,4080.0
9.280271868,4028.0
9.332792995,3953.0
9.385314123,4036.0
9.437835250,4158.0
9.490356377,4037.0
9.542877504,4129.0
9.595398632,4006.0
9.647919759,4059.0
9.700440886,3981.0
9.752962013,4081.0
9.805483141,3936.0
9.858004268,3903.0
9.910525395,4021.0
9.963046522,3963.0
10.015567650,3861.0
10.068088777,3852.0
10.120609904,3907.0
10.173131031,3898.0
10.225652159,3914.0
10.278173286,3962.0
10.330694413,3819.0
10.383215541,3771.0
10.435736668,3904.0
10.488257795,3732.0
10.540778922,3853.0
10.593300050,3918.0
10.645821177,3900.0
10.698342304,3857.0
10.750863431,3875.0
10.803384559,3803.0
10.855905686,3842.0
10.908426813,3678.0
10.960947940,3779.0
11.013469068,3796.0
11.065990195,3662.0
11.118511322,3582.0
11.171032449,3708.0
11.223553577,3785.0
11.276074704,3622.0
11.328595831,3642.0
11.381116958,3735.0
11.433638086,3583.0
11.486159213,3610.0
11.538680340,3573.0
11.591201467,3735.0
11.643722595,3705.0
11.696243722,3597.0
11.748764849,3563.0
11.801285977,3635.0
11.853807104,3666.0
11.906328231,3497.0
11.958849358,3480.0
12.011370486,3582.0
12.063891613,3529.0
12.116412740,3618.0
12.168933867,3541.0
12.221454995,3499.0
12.273976122,3562.0
12.326497249,3474.0
12.379018376,3489.0
12.431539504,3556.0
12.484060631,3549.0
12.536581758,3553.0
12.589102885,3478.0
12.641624013,3519.0
12.694145140,3596.0
12.746666267,3335.0
12.799187394,3466.0
12.851708522,3465.0
12.904229649,3373.0
12.956750776,3459.0
13.009271904,3385.0
13.061793031,3420.0
13.114314158,3457.0
13.166835285,3433.0
13.219356413,3353.0
13.271877540,3345.0
13.324398667,3399.0
13.376919794,3316.0
13.429440922,3307.0
13.481962049,3210.0
13.534483176,3301.0
13.587004303,3351.0
13.639525431,3417.0
13.692046558,3368.0
13.744567685,3359.0
13.797088812,3391.0
13.849609940,3319.0
13.902131067,3261.0
13.954652194,3448.0
14.007173321,3304.0
14.059694449,3228.0
14.112215576,3278.0
14.164736703,3129.0
14.217257830,3213.0
14.269778958,3218.0
14.322300085,3256.0
14.374821212,3253.0
14.427342340,3224.0
14.479863467,3260.0
14.532384594,3245.0
14.584905721,3247.0
14.637426849,3176.0
14.689947976,3128.0
14.742469103,3152.0
14.794990230,3197.0
14.847511358,3275.0
14.900032485,3165.0
14.952553612,3151.0
15.005074739,3159.0
15.057595867,3125.0
15.110116994,3120.0
15.162638121,3075.0
15.215159248,3027.0
15.267680376,3177.0
15.320201503,3099.0
15.372722630,3110.0
15.425243757,3002.0
15.477764885,3014.0
15.530286012,3209.0
15.582807139,3052.0
15.635328267,3005.0
15.687849394,2867.0
15.740370521,3024.0
15.792891648,2896.0
15.845412776,2986.0
15.897933903,2950.0
15.950455030,2966.0
16.002976157,3055.0
16.055497285,2906.0
16.108018412,2973.0
16.160539539,2917.0
16.213060666,2931.0
16.265581794,2943.0
16.318102921,2943.0
16.370624048,2855.0
16.423145175,3026.0
16.475666303,2907.0
16.528187430,2804.0
16.580708557,2858.0
16.633229684,2939.0
16.685750812,2918.0
16.738271939,2831.0
16.790793066,2935.0
16.843314193,2776.0
16.895835321,2939.0
16.948356448,2744.0
17.000877575,2825.0
17.053398703,2838.0
17.105919830,2825.0
17.158440957,2757.0
17.210962084,2728.0
17.263483212,2768.0
17.316004339,2812.0
17.368525466,2767.0
17.421046593,2662.0
17.473567721,2695.0
17.526088848,2753.0
17.578609975,2594.0
17.631131102,2685.0
17.683652230,2741.0
17.736173357,2637.0
17.788694484,2700.0
17.841215611,2667.0
17.893736739,2792.0
17.946257866,2740.0
17.998778993,2685.0
18.051300120,2739.0
18.103821248,2689.0
18.156342375,2668.0
18.208863502,2675.0
18.261384630,2613.0
18.313905757,2630.0
18.366426884,2567.0
18.418948011,2665.0
18.471469139,2676.0
18.523990266,2604.0
18.576511393,2659.0
18.629032520,2547.0
18.681553648,2519.0
18.734074775,2475.0
18.786595902,2639.0
18.839117029,2599.0
18.891638157,2624.0
18.944159284,2659.0
18.996680411,2596.0
19.049201538,2642.0
19.101722666,2561.0
19.154243793,2586.0
19.206764920,2628.0
19.259286047,2541.0
19.311807175,2697.0
19.364328302,2567.0
19.416849429,2557.0
19.469370556,2676.0
19.521891684,2540.0
19.574412811,2528.0
19.626933938,2580.0
19.679455066,2558.0
19.731976193,2521.0
19.784497320,2494.0
19.837018447,2515.0
19.889539575,2519.0
19.942060702,2444.0
19.994581829,2467.0
20.047102956,2485.0
20.099624084,2453.0
20.152145211,2500.0
20.204666338,2498.0
20.257187465,2462.0
20.309708593,2551.0
20.362229720,2491.0
20.414750847,2469.0
20.467271974,2515.0
20.519793102,2532.0
20.572314229,2435.0
20.624835356,2567.0
20.677356483,2368.0
20.729877611,2485.0
20.782398738,2392.0
20.834919865,2541.0
20.887440993,2517.0
20.939962120,2364.0
20.992483247,2528.0
21.045004374,2421.0
21.097525502,2445.0
21.150046629,2437.0
21.202567756,2484.0
21.255088883,2418.0
21.307610011,2439.0
21.360131138,2378.0
21.412652265,2433.0
21.465173392,2365.0
21.517694520,2371.0
21.570215647,2287.0
21.622736774,2524.0
21.675257901,2249.0
21.727779029,2472.0
21.780300156,2491.0
21.832821283,2337.0
21.885342410,2405.0
21.937863538,2372.0
21.990384665,2359.0
22.042905792,2362.0
22.095426919,2291.0
22.147948047,2351.0
22.200469174,2353.0
22.252990301,2262.0
22.305511429,2385.0
22.358032556,2307.0
22.410553683,2278.0
22.463074810,2326.0
22.515595938,2440.0
22.568117065,2198.0
22.620638192,2356.0
22.673159319,2304.0
22.725680447,2354.0
22.778201574,2292.0
22.830722701,2356.0
22.883243828,2359.0
22.935764956,2347.0
22.988286083,2343.0
23.040807210,2353.0
23.093328337,2183.0
23.145849465,2340.0
23.198370592,2327.0
23.250891719,2295.0
23.303412846,2208.0
23.355933974,2268.0
23.408455101,2252.0
23.460976228,2300.0
23.513497356,2296.0
23.566018483,2373.0
23.618539610,2202.0
23.671060737,2233.0
23.723581865,2217.0
23.776102992,2283.0
23.828624119,2259.0
23.881145246,2318.0
23.933666374,2266.0
23.986187501,2249.0
24.038708628,2334.0
24.091229755,2185.0
24.143750883,2287.0
24.196272010,2282.0
24.248793137,2340.0
24.301314264,2290.0
24.353835392,2166.0
24.406356519,2146.0
24.458877646,2115.0
24.511398773,2279.0
24.563919901,2297.0
24.616441028,2161.0
24.668962155,2159.0
24.721483282,2236.0
24.774004410,2197.0
24.826525537,2209.0
24.879046664,2215.0
24.931567792,2253.0
24.984088919,2245.0
25.036610046,2171.0
25.089131173,2230.0
25.141652301,2209.0
25.194173428,2186.0
25.246694555,2206.0
25.299215682,2256.0
25.351736810,2181.0
25.404257937,2234.0
25.456779064,2191.0
25.509300191,2299.0
25.561821319,2272.0
25.614342446,2218.0
25.666863573,2188.0
25.719384700,2286.0
25.771905828,2189.0
25.824426955,2345.0
25.876948082,2293.0
25.929469209,2198.0
25.981990337,2155.0
26.034511464,2179.0
26.087032591,2226.0
26.139553719,2190.0
26.192074846,2154.0
26.244595973,2258.0
26.297117100,2206.0
26.349638228,2212.0
26.402159355,2196.0
26.454680482,2200.0
26.507201609,2272.0
26.559722737,2193.0
26.612243864,2331.0
26.664764991,2394.0
26.717286118,2295.0
26.769807246,2164.0
26.822328373,2163.0
26.874849500,2121.0
26.927370627,2186.0
26.979891755,2159.0
27.032412882,2228.0
27.084934009,2117.0
27.137455136,2282.0
27.189976264,2175.0
27.242497391,2139.0
27.295018518,2264.0
27.347539645,2171.0
27.400060773,2185.0
27.452581900,2254.0
27.505103027,2183.0
27.557624155,2235.0
27.610145282,2163.0
27.662666409,2240.0
27.715187536,2330.0
27.767708664,2271.0
27.820229791,2316.0
27.872750918,2291.0
27.925272045,2310.0
27.977793173,2231.0
28.030314300,2267.0
28.082835427,2273.0
28.135356554,2325.0
28.187877682,2321.0
28.240398809,2399.0
28.292919936,2589.0
28.345441063,2695.0
28.397962191,3042.0
28.450483318,3520.0
28.503004445,4684.0
28.555525572,7189.0
28.608046700,13828.0
28.660567827,24520.0
28.713088954,21644.0
28.765610082,13162.0
28.818131209,5364.0
28.870652336,3428.0
28.923173463,2792.0
28.975694591,2541.0
29.028215718,2294.0
29.080736845,2321.0
29.133257972,2239.0
29.185779100,2336.0
29.238300227,2221.0
29.290821354,2164.0
29.343342481,2124.0
29.395863609,2195.0
29.448384736,2172.0
29.500905863,2088.0
29.553426990,2168.0
29.605948118,2056.0
29.658469245,2108.0
29.710990372,2060.0
29.763511499,1995.0
29.816032627,2064.0
29.868553754,2117.0
29.921074881,2106.0
29.973596008,2089.0
30.026117136,2045.0
30.078638263,2081.0
30.131159390,2099.0
30.183680518,2040.0
30.236201645,2016.0
30.288722772,1971.0
30.341243899,2068.0
30.393765027,1974.0
30.446286154,2021.0
30.498807281,2043.0
30.551328408,1997.0
30.603849536,2069.0
30.656370663,1994.0
30.708891790,2044.0
30.761412917,1982.0
30.813934045,2067.0
30.866455172,2106.0
30.918976299,2217.0
30.971497426,2189.0
31.024018554,2121.0
31.076539681,2014.0
31.129060808,2014.0
31.181581935,1951.0
31.234103063,1892.0
31.286624190,1888.0
31.339145317,2031.0
31.391666445,1944.0
31.444187572,1922.0
31.496708699,1971.0
31.549229826,1948.0
31.601750954,1997.0
31.654272081,1978.0
31.706793208,1909.0
31.759314335,1947.0
31.811835463,2004.0
31.864356590,1885.0
31.916877717,1921.0
31.969398844,1879.0
32.021919972,1955.0
32.074441099,1980.0
32.126962226,1957.0
32.179483353,1992.0
32.232004481,1962.0
32.284525608,1942.0
32.337046735,1904.0
32.389567862,1896.0
32.442088990,1886.0
32.494610117,1941.0
32.547131244,1944.0
32.599652371,1888.0
32.652173499,1890.0
32.704694626,1992.0
32.757215753,1861.0
32.809736881,1878.0
32.862258008,1904.0
32.914779135,1917.0
32.967300262,1975.0
33.019821390,1931.0
33.072342517,1881.0
33.124863644,1928.0
33.177384771,1929.0
33.229905899,1950.0
33.282427026,1862.0
33.334948153,1947.0
33.387469280,1793.0
33.439990408,1946.0
33.492511535,1917.0
33.545032662,1945.0
33.597553789,1841.0
33.650074917,1901.0
33.702596044,1870.0
33.755117171,1902.0
33.807638298,1912.0
33.860159426,1894.0
33.912680553,1949.0
33.965201680,1957.0
34.017722808,1962.0
34.070243935,1943.0
34.122765062,1891.0
34.175286189,1917.0
34.227807317,1922.0
34.280328444,1824.0
34.332849571,1926.0
34.385370698,1882.0
34.437891826,1860.0
34.490412953,1993.0
34.542934080,1883.0
34.595455207,1888.0
34.647976335,1895.0
34.700497462,1893.0
34.753018589,1852.0
34.805539716,1964.0
34.858060844,2023.0
34.910581971,1956.0
34.963103098,2043.0
35.015624225,1927.0
35.068145353,1916.0
35.120666480,1904.0
35.173187607,1969.0
35.225708734,2044.0
35.278229862,1952.0
35.330750989,2029.0
35.383272116,1972.0
35.435793244,1922.0
35.488314371,2003.0
35.540835498,1963.0
35.593356625,1979.0
35.645877753,2014.0
35.698398880,1966.0
35.750920007,2029.0
35.803441134,2078.0
35.855962262,1951.0
35.908483389,1995.0
35.961004516,2032.0
36.013525643,2065.0
36.066046771,2034.0
36.118567898,2026.0
36.171089025,1962.0
36.223610152,1997.0
36.276131280,2023.0
36.328652407,2034.0
36.381173534,2087.0
36.433694661,1998.0
36.486215789,2014.0
36.538736916,2087.0
36.591258043,2094.0
36.643779171,2163.0
36.696300298,2057.0
36.748821425,2060.0
36.801342552,2008.0
36.853863680,2052.0
36.906384807,2058.0
36.958905934,2050.0
37.011427061,2124.0
37.063948189,2110.0
37.116469316,2172.0
37.168990443,2212.0
37.221511570,2603.0
37.274032698,3146.0
37.326553825,4185.0
37.379074952,4635.0
37.431596079,4043.0
37.484117207,3463.0
37.536638334,2760.0
37.589159461,2307.0
37.641680588,2140.0
37.694201716,2119.0
37.746722843,2047.0
37.799243970,1992.0
37.851765097,1995.0
37.904286225,1957.0
37.956807352,2005.0
38.009328479,2001.0
38.061849607,1917.0
38.114370734,1956.0
38.166891861,1997.0
38.219412988,1984.0
38.271934116,1967.0
38.324455243,1972.0
38.376976370,1974.0
38.429497497,2017.0
38.482018625,1955.0
38.534539752,1963.0
38.587060879,1992.0
38.639582006,1915.0
38.692103134,1957.0
38.744624261,1952.0
38.797145388,1966.0
38.849666515,1964.0
38.902187643,1834.0
38.954708770,1917.0
39.007229897,1994.0
39.059751024,1974.0
39.112272152,1958.0
39.164793279,1950.0
39.217314406,1884.0
39.269835534,1910.0
39.322356661,1901.0
39.374877788,1894.0
39.427398915,1952.0
39.479920043,1963.0
39.532441170,1938.0
39.584962297,1931.0
39.637483424,1882.0
39.690004552,1887.0
39.742525679,1915.0
39.795046806,1780.0
39.847567933,1909.0
39.900089061,1896.0
39.952610188,1866.0
40.005131315,1868.0
40.057652442,1846.0
40.110173570,1864.0
40.162694697,1826.0
40.215215824,1896.0
40.267736951,1944.0
40.320258079,1861.0
40.372779206,1870.0
40.425300333,1953.0
40.477821460,1938.0
40.530342588,2044.0
40.582863715,1979.0
40.635384842,2138.0
40.687905970,2175.0
40.740427097,2421.0
40.792948224,2583.0
40.845469351,2704.0
40.897990479,2831.0
40.950511606,2880.0
41.003032733,2869.0
41.055553860,2887.0
41.108074988,2787.0
41.160596115,2653.0
41.213117242,2549.0
41.265638369,2292.0
41.318159497,2194.0
41.370680624,2052.0
41.423201751,2011.0
41.475722878,1948.0
41.528244006,1905.0
41.580765133,1851.0
41.633286260,1924.0
41.685807387,1966.0
41.738328515,1906.0
41.790849642,1975.0
41.843370769,1866.0
41.895891897,1866.0
41.948413024,1878.0
42.000934151,1851.0
42.053455278,1925.0
42.105976406,1897.0
42.158497533,1900.0
42.211018660,1776.0
42.263539787,1857.0
42.316060915,1862.0
42.368582042,1819.0
42.421103169,1857.0
42.473624296,1826.0
42.526145424,1841.0
42.578666551,1833.0
42.631187678,1895.0
42.683708805,1930.0
42.736229933,2250.0
42.788751060,2839.0
42.841272187,2906.0
42.893793314,2442.0
42.946314442,2363.0
42.998835569,1971.0
43.051356696,1849.0
43.103877823,1917.0
43.156398951,1881.0
43.208920078,1892.0
43.261441205,1896.0
43.313962333,1853.0
43.366483460,1835.0
43.419004587,1795.0
43.471525714,1820.0
43.524046842,1801.0
43.576567969,1863.0
43.629089096,1795.0
43.681610223,1922.0
43.734131351,1808.0
43.786652478,1901.0
43.839173605,1876.0
43.891694732,1841.0
43.944215860,1853.0
43.996736987,1826.0
44.049258114,1857.0
44.101779241,1782.0
44.154300369,1927.0
44.206821496,1855.0
44.259342623,1906.0
44.311863750,1871.0
44.364384878,1784.0
44.416906005,1823.0
44.469427132,1837.0
44.521948260,1883.0
44.574469387,1771.0
44.626990514,1830.0
44.679511641,1874.0
44.732032769,1869.0
44.784553896,1804.0
44.837075023,1905.0
44.889596150,1797.0
44.942117278,1915.0
44.994638405,1856.0
45.047159532,1842.0
45.099680659,1880.0
45.152201787,1915.0
45.204722914,1842.0
45.257244041,1808.0
45.309765168,1842.0
45.362286296,1824.0
45.414807423,1878.0
45.467328550,1811.0
45.519849677,1784.0
45.572370805,1912.0
45.624891932,1892.0
45.677413059,1889.0
45.729934186,1920.0
45.782455314,1849.0
45.834976441,1981.0
45.887497568,2083.0
45.940018696,2215.0
45.992539823,2258.0
46.045060950,2349.0
46.097582077,2505.0
46.150103205,2445.0
46.202624332,2246.0
46.255145459,2130.0
46.307666586,2157.0
46.360187714,1986.0
46.412708841,1865.0
46.465229968,1844.0
46.517751095,1897.0
46.570272223,1846.0
46.622793350,1809.0
46.675314477,1799.0
46.727835604,1881.0
46.780356732,1818.0
46.832877859,1768.0
46.885398986,1824.0
46.937920113,1839.0
46.990441241,1897.0
47.042962368,1881.0
47.095483495,1780.0
47.148004623,1757.0
47.200525750,1836.0
47.253046877,1892.0
47.305568004,1888.0
47.358089132,1912.0
47.410610259,1894.0
47.463131386,1882.0
47.515652513,1945.0
47.568173641,1795.0
47.620694768,1875.0
47.673215895,1883.0
47.725737022,1893.0
47.778258150,1830.0
47.830779277,1846.0
47.883300404,1862.0
47.935821531,1784.0
47.988342659,1809.0
48.040863786,1818.0
48.093384913,1897.0
48.145906040,1978.0
48.198427168,1862.0
48.250948295,1944.0
48.303469422,1819.0
48.355990549,1848.0
48.408511677,1825.0
48.461032804,1897.0
48.513553931,1882.0
48.566075059,1861.0
48.618596186,1900.0
48.671117313,1835.0
48.723638440,1885.0
48.776159568,1886.0
48.828680695,1847.0
48.881201822,1845.0
48.933722949,1902.0
48.986244077,1893.0
49.038765204,1848.0
49.091286331,1933.0
49.143807458,1835.0
49.196328586,1912.0
49.248849713,1895.0
49.301370840,1967.0
49.353891967,1920.0
49.406413095,1864.0
49.458934222,1883.0
49.511455349,1861.0
49.563976476,1870.0
49.616497604,1950.0
49.669018731,1870.0
49.721539858,1883.0
49.774060986,1941.0
49.826582113,1857.0
49.879103240,1895.0
49.931624367,1878.0
49.984145495,1812.0
50.036666622,1911.0
50.089187749,1917.0
50.141708876,1937.0
50.194230004,1881.0
50.246751131,1841.0
50.299272258,1873.0
50.351793385,1955.0
50.404314513,1885.0
50.456835640,1898.0
50.509356767,1935.0
50.561877894,2029.0
50.614399022,1879.0
50.666920149,1898.0
50.719441276,1934.0
50.771962403,1914.0
50.824483531,1875.0
50.877004658,1884.0
50.929525785,1909.0
50.982046912,1836.0
51.034568040,1812.0
51.087089167,1844.0
51.139610294,1833.0
51.192131422,1851.0
51.244652549,1899.0
51.297173676,1819.0
51.349694803,1927.0
51.402215931,1975.0
51.454737058,1827.0
51.507258185,1835.0
51.559779312,1961.0
51.612300440,1826.0
51.664821567,1774.0
51.717342694,1950.0
51.769863821,1804.0
51.822384949,1887.0
51.874906076,1849.0
51.927427203,1928.0
51.979948330,1868.0
52.032469458,1773.0
52.084990585,1813.0
52.137511712,1879.0
52.190032839,1854.0
52.242553967,1828.0
52.295075094,1861.0
52.347596221,1811.0
52.400117349,1841.0
52.452638476,1837.0
52.505159603,1867.0
52.557680730,1925.0
52.610201858,1925.0
52.662722985,1829.0
52.715244112,1823.0
52.767765239,1864.0
52.820286367,1819.0
52.872807494,1843.0
52.925328621,1788.0
52.977849748,1874.0
53.030370876,1900.0
53.082892003,1810.0
53.135413130,1838.0
53.187934257,1969.0
53.240455385,1883.0
53.292976512,1881.0
53.345497639,1917.0
53.398018766,1876.0
53.450539894,1894.0
53.503061021,1834.0
53.555582148,1866.0
53.608103275,1887.0
53.660624403,1866.0
53.713145530,1816.0
53.765666657,1845.0
53.818187785,1874.0
53.870708912,1846.0
53.923230039,1813.0
53.975751166,1825.0
54.028272294,1872.0
54.080793421,1802.0
54.133314548,1878.0
54.185835675,1870.0
54.238356803,1937.0
54.290877930,1855.0
54.343399057,1925.0
54.395920184,1800.0
54.448441312,1844.0
54.500962439,1853.0
54.553483566,1828.0
54.606004693,1848.0
54.658525821,1886.0
54.711046948,1904.0
54.763568075,1879.0
54.816089202,1863.0
54.868610330,1923.0
54.921131457,1929.0
54.973652584,1896.0
55.026173712,1875.0
55.078694839,1887.0
55.131215966,1796.0
55.183737093,1897.0
55.236258221,1876.0
55.288779348,1892.0
55.341300475,1900.0
55.393821602,1903.0
55.446342730,1898.0
55.498863857,1897.0
55.551384984,2010.0
55.603906111,1830.0
55.656427239,1833.0
55.708948366,1907.0
55.761469493,1894.0
55.813990620,1821.0
55.866511748,1890.0
55.919032875,1932.0
55.971554002,1867.0
56.024075129,1943.0
56.076596257,1895.0
56.129117384,1844.0
56.181638511,1984.0
56.234159638,1949.0
56.286680766,2105.0
56.339201893,2063.0
56.391723020,2179.0
56.444244148,2545.0
56.496765275,2973.0
56.549286402,3518.0
56.601807529,3970.0
56.654328657,4433.0
56.706849784,4628.0
56.759370911,4208.0
56.811892038,3666.0
56.864413166,3296.0
56.916934293,2798.0
56.969455420,2404.0
57.021976547,2105.0
57.074497675,1972.0
57.127018802,1917.0
57.179539929,1890.0
57.232061056,1835.0
57.284582184,1877.0
57.337103311,1846.0
57.389624438,1867.0
57.442145565,1841.0
57.494666693,1806.0
57.547187820,1803.0
57.599708947,1804.0
57.652230075,1868.0
57.704751202,1885.0
57.757272329,1687.0
57.809793456,1796.0
57.862314584,1726.0
57.914835711,1624.0
57.967356838,1722.0
58.019877965,1744.0
58.072399093,1747.0
58.124920220,1774.0
58.177441347,1816.0
58.229962474,1729.0
58.282483602,1764.0
58.335004729,1700.0
58.387525856,1783.0
58.440046983,1747.0
58.492568111,1750.0
58.545089238,1759.0
58.597610365,1793.0
58.650131492,1740.0
58.702652620,1749.0
58.755173747,1794.0
58.807694874,1748.0
58.860216001,1708.0
58.912737129,1731.0
58.965258256,1726.0
59.017779383,1757.0
59.070300511,1884.0
59.122821638,1851.0
59.175342765,1993.0
59.227863892,2359.0
59.280385020,2871.0
59.332906147,3844.0
59.385427274,3925.0
59.437948401,3051.0
59.490469529,2964.0
59.542990656,2921.0
59.595511783,2276.0
59.648032910,1932.0
59.700554038,1686.0
59.753075165,1717.0
59.805596292,1740.0
59.858117419,1802.0
59.910638547,1790.0
59.963159674,1769.0
60.015680801,1696.0
60.068201928,1680.0
60.120723056,1648.0
60.173244183,1643.0
60.225765310,1670.0
60.278286438,1719.0
60.330807565,1642.0
60.383328692,1617.0
60.435849819,1655.0
60.488370947,1635.0
60.540892074,1655.0
60.593413201,1640.0
60.645934328,1690.0
60.698455456,1628.0
60.750976583,1701.0
60.803497710,1677.0
60.856018837,1649.0
60.908539965,1652.0
60.961061092,1640.0
61.013582219,1585.0
61.066103346,1728.0
61.118624474,1668.0
61.171145601,1708.0
61.223666728,1623.0
61.276187855,1639.0
61.328708983,1685.0
61.381230110,1715.0
61.433751237,1687.0
61.486272364,1689.0
61.538793492,1627.0
61.591314619,1676.0
61.643835746,1651.0
61.696356874,1744.0
61.748878001,1676.0
61.801399128,1632.0
61.853920255,1714.0
61.906441383,1693.0
61.958962510,1691.0
62.011483637,1619.0
62.064004764,1734.0
62.116525892,1700.0
62.169047019,1654.0
62.221568146,1726.0
62.274089273,1725.0
62.326610401,1655.0
62.379131528,1664.0
62.431652655,1723.0
62.484173782,1746.0
62.536694910,1681.0
62.589216037,1688.0
62.641737164,1664.0
62.694258291,1633.0
62.746779419,1728.0
62.799300546,1647.0
62.851821673,1670.0
62.904342801,1636.0
62.956863928,1627.0
63.009385055,1646.0
63.061906182,1648.0
63.114427310,1652.0
63.166948437,1698.0
63.219469564,1677.0
63.271990691,1684.0
63.324511819,1708.0
63.377032946,1697.0
63.429554073,1709.0
63.482075200,1698.0
63.534596328,1700.0
63.587117455,1677.0
63.639638582,1662.0
63.692159709,1687.0
63.744680837,1732.0
63.797201964,1681.0
63.849723091,1644.0
63.902244218,1717.0
63.954765346,1643.0
64.007286473,1752.0
64.059807600,1679.0
64.112328727,1683.0
64.164849855,1624.0
64.217370982,1731.0
64.269892109,1678.0
64.322413237,1655.0
64.374934364,1662.0
64.427455491,1655.0
64.479976618,1620.0
64.532497746,1694.0
64.585018873,1669.0
64.637540000,1715.0
64.690061127,1623.0
64.742582255,1687.0
64.795103382,1774.0
64.847624509,1884.0
64.900145636,1887.0
64.952666764,1848.0
65.005187891,1809.0
65.057709018,1777.0
65.110230145,1734.0
65.162751273,1642.0
65.215272400,1734.0
65.267793527,1616.0
65.320314654,1656.0
65.372835782,1713.0
65.425356909,1615.0
65.477878036,1723.0
65.530399164,1672.0
65.582920291,1632.0
65.635441418,1624.0
65.687962545,1628.0
65.740483673,1583.0
65.793004800,1615.0
65.845525927,1664.0
65.898047054,1555.0
65.950568182,1647.0
66.003089309,1652.0
66.055610436,1570.0
66.108131563,1614.0
66.160652691,1659.0
66.213173818,1665.0
66.265694945,1637.0
66.318216072,1650.0
66.370737200,1629.0
66.423258327,1611.0
66.475779454,1658.0
66.528300581,1677.0
66.580821709,1738.0
66.633342836,1709.0
66.685863963,1685.0
66.738385090,1685.0
66.790906218,1774.0
66.843427345,1853.0
66.895948472,1857.0
66.948469600,1992.0
67.000990727,1993.0
67.053511854,2063.0
67.106032981,2081.0
67.158554109,2138.0
67.211075236,2081.0
67.263596363,2082.0
67.316117490,2051.0
67.368638618,2132.0
67.421159745,2071.0
67.473680872,2034.0
67.526201999,2049.0
67.578723127,1960.0
67.631244254,1823.0
67.683765381,1784.0
67.736286508,1685.0
67.788807636,1696.0
67.841328763,1775.0
67.893849890,1600.0
67.946371017,1663.0
67.998892145,1662.0
68.051413272,1604.0
68.103934399,1600.0
68.156455527,1610.0
68.208976654,1585.0
68.261497781,1594.0
68.314018908,1595.0
68.366540036,1642.0
68.419061163,1596.0
68.471582290,1608.0
68.524103417,1602.0
68.576624545,1655.0
68.629145672,1684.0
68.681666799,1595.0
68.734187926,1650.0
68.786709054,1602.0
68.839230181,1676.0
68.891751308,1612.0
68.944272435,1655.0
68.996793563,1662.0
69.049314690,1599.0
69.101835817,1619.0
69.154356944,1705.0
69.206878072,1628.0
69.259399199,1599.0
69.311920326,1616.0
69.364441453,1601.0
69.416962581,1547.0
69.469483708,1649.0
69.522004835,1605.0
69.574525963,1593.0
69.627047090,1696.0
69.679568217,1697.0
69.732089344,1611.0
69.784610472,1628.0
69.837131599,1618.0
69.889652726,1548.0
69.942173853,1673.0
69.994694981,1629.0
70.047216108,1627.0
70.099737235,1565.0
70.152258362,1602.0
70.204779490,1615.0
70.257300617,1634.0
70.309821744,1589.0
70.362342871,1616.0
70.414863999,1677.0
70.467385126,1627.0
70.519906253,1591.0
70.572427380,1618.0
70.624948508,1555.0
70.677469635,1634.0
70.729990762,1548.0
70.782511890,1654.0
70.835033017,1621.0
70.887554144,1607.0
70.940075271,1674.0
70.992596399,1611.0
71.045117526,1668.0
71.097638653,1562.0
71.150159780,1673.0
71.202680908,1701.0
71.255202035,1690.0
71.307723162,1601.0
71.360244289,1685.0
71.412765417,1703.0
71.465286544,1680.0
71.517807671,1690.0
71.570328798,1642.0
71.622849926,1695.0
71.675371053,1834.0
71.727892180,1781.0
71.780413307,1758.0
71.832934435,1877.0
71.885455562,1947.0
71.937976689,1873.0
71.990497816,2046.0
72.043018944,1940.0
72.095540071,2113.0
72.148061198,2166.0
72.200582326,2134.0
72.253103453,2106.0
72.305624580,2375.0
72.358145707,2389.0
72.410666835,2498.0
72.463187962,2457.0
72.515709089,2235.0
72.568230216,2243.0
72.620751344,2145.0
72.673272471,2150.0
72.725793598,1929.0
72.778314725,1805.0
72.830835853,1814.0
72.883356980,1803.0
72.935878107,1755.0
72.988399234,1766.0
73.040920362,1703.0
73.093441489,1677.0
73.145962616,1664.0
73.198483743,1724.0
73.251004871,1648.0
73.303525998,1644.0
73.356047125,1626.0
73.408568253,1634.0
73.461089380,1663.0
73.513610507,1653.0
73.566131634,1613.0
73.618652762,1693.0
73.671173889,1662.0
73.723695016,1564.0
73.776216143,1684.0
73.828737271,1673.0
73.881258398,1673.0
73.933779525,1625.0
73.986300652,1604.0
74.038821780,1694.0
74.091342907,1748.0
74.143864034,1734.0
74.196385161,1622.0
74.248906289,1650.0
74.301427416,1630.0
74.353948543,1715.0
74.406469670,1577.0
74.458990798,1630.0
74.511511925,1648.0
74.564033052,1616.0
74.616554179,1663.0
74.669075307,1673.0
74.721596434,1649.0
74.774117561,1693.0
74.826638689,1712.0
74.879159816,1620.0
74.931680943,1655.0
74.984202070,1658.0
75.036723198,1636.0
75.089244325,1652.0
75.141765452,1704.0
75.194286579,1717.0
75.246807707,1667.0
75.299328834,1723.0
75.351849961,1663.0
75.404371088,1720.0
75.456892216,1612.0
75.509413343,1645.0
75.561934470,1694.0
75.614455597,1646.0
75.666976725,1685.0
75.719497852,1728.0
75.772018979,1678.0
75.824540106,1717.0
75.877061234,1725.0
75.929582361,1758.0
75.982103488,1793.0
76.034624616,1783.0
76.087145743,1673.0
76.139666870,1747.0
76.192187997,1675.0
76.244709125,1714.0
76.297230252,1680.0
76.349751379,1763.0
76.402272506,1717.0
76.454793634,1762.0
76.507314761,1685.0
76.559835888,1705.0
76.612357015,1641.0
76.664878143,1680.0
76.717399270,1641.0
76.769920397,1740.0
76.822441524,1713.0
76.874962652,1663.0
76.927483779,1745.0
76.980004906,1705.0
77.032526033,1720.0
77.085047161,1787.0
77.137568288,1668.0
77.190089415,1663.0
77.242610542,1760.0
77.295131670,1734.0
77.347652797,1736.0
77.400173924,1753.0
77.452695052,1743.0
77.505216179,1740.0
77.557737306,1726.0
77.610258433,1716.0
77.662779561,1709.0
77.715300688,1684.0
77.767821815,1691.0
77.820342942,1711.0
77.872864070,1631.0
77.925385197,1747.0
77.977906324,1665.0
78.030427451,1737.0
78.082948579,1819.0
78.135469706,1802.0
78.187990833,1696.0
78.240511960,1720.0
78.293033088,1704.0
78.345554215,1700.0
78.398075342,1657.0
78.450596469,1703.0
78.503117597,1715.0
78.555638724,1699.0
78.608159851,1720.0
78.660680979,1630.0
78.713202106,1721.0
78.765723233,1680.0
78.818244360,1704.0
78.870765488,1700.0
78.923286615,1655.0
78.975807742,1698.0
79.028328869,1689.0
79.080849997,1701.0
79.133371124,1630.0
79.185892251,1621.0
79.238413378,1671.0
79.290934506,1613.0
79.343455633,1736.0
79.395976760,1752.0
79.448497887,1712.0
79.501019015,1755.0
79.553540142,1714.0
79.606061269,1770.0
79.658582396,1727.0
79.711103524,1747.0
79.763624651,1731.0
79.816145778,1745.0
79.868666905,1651.0
79.921188033,1689.0
79.973709160,1681.0